Workbook

Sheet Main
A1: repository_owner | B1: repository_name | C1: file_url | D1: sentence_index | E1: sentence_content | F1: Keywords (automatic) | G1: Type of Prohibition
A2: langchain-ai | B2: langchain | C2: https://github.com/langchain-ai/langchain/blob/master/CLAUDE.md | D2: 40 | E2: - Do **not** cite line numbers; they go stale as soon as the file changes. | F2: Do **not** | G2: Commit&PR rule
A3: module-federation | B3: core | C3: https://github.com/module-federation/core/blob/main/CLAUDE.md | D3: 103 | E3: - ✗ Use a single task when multiple would be faster | F3: ✗ | G3: Task Execution
A4: module-federation | B4: core | C4: https://github.com/module-federation/core/blob/main/CLAUDE.md | D4: 104 | E4: - ✗ Ask for clarification before launching tasks | F4: ✗ | G4: Task Execution
A5: module-federation | B5: core | C5: https://github.com/module-federation/core/blob/main/CLAUDE.md | D5: 105 | E5: - ✗ Make tasks dependent on each other | F5: ✗ | G5: Task Execution
A6: module-federation | B6: core | C6: https://github.com/module-federation/core/blob/main/CLAUDE.md | D6: 106 | E6: - ✗ Load entire codebase into a single task | F6: ✗ | G6: Task Execution
A7: module-federation | B7: core | C7: https://github.com/module-federation/core/blob/main/CLAUDE.md | D7: 107 | E7: - ✗ Create documentation unless specifically requested | F7: ✗ | G7: Documentation
A8: module-federation | B8: core | C8: https://github.com/module-federation/core/blob/main/CLAUDE.md | D8: 112 | E8: - ✗ Create new files when existing ones can be modified | F8: ✗ | G8: Task Execution
A9: owid | B9: owid-grapher | C9: https://github.com/owid/owid-grapher/blob/master/CLAUDE.md | D9: 20 | E9: The `makeObservable` call must mention all obserable props, but none of the @computed or @action ones. | F9: none of | G9: Coding Pattern
A10: saleor | B10: saleor | C10: https://github.com/saleor/saleor/blob/main/CLAUDE.md | D10: 20 | E10: - When asserting to Enum, import enum in a test file and use `assert error.code == MyEnum.SOME_ERROR.name` instead of plain string comparison | F10: instead of | G10: Coding Pattern
A11: zed-industries | B11: zed | C11: https://github.com/zed-industries/zed/blob/main/CLAUDE.md | D11: 111 | E11: Do **not** edit `.rules` inline during normal feature/fix work. | F11: Do **not** | G11: Documentation
A12: gluesql | B12: glues | C12: https://github.com/gluesql/glues/blob/main/AGENTS.md | D12: 4 | E12: - Use file-based module declarations; do **not** introduce `mod.rs` files. | F12: Do **not** | G12: Coding Pattern
A13: useautumn | B13: autumn | C13: https://github.com/useautumn/autumn/blob/main/AGENTS.md | D13: 30 | E13: - Do **not** remove or bypass logic in `server/src/honoMiddlewares/refreshCacheMiddleware.ts` unless the user explicitly asks to change middleware behavior globally. | F13: Do **not** | G13: Coding Pattern
A14: Azure | B14: fleet | C14: https://github.com/Azure/fleet/blob/main/.github/copilot-instructions.md | D14: 32 | E14: - Do **not** use assert libraries; use `cmp.Diff` / `cmp.Equal` from `google/go-cmp` for comparisons | F14: Do **not** | G14: Coding Pattern
A15: dotnet | B15: java-interop | C15: https://github.com/dotnet/java-interop/blob/main/.github/copilot-instructions.md | D15: 46 | E15: * Use `""` for empty string and *not* `string.Empty` | G15: Coding Pattern
A16: dotnet | B16: java-interop | C16: https://github.com/dotnet/java-interop/blob/main/.github/copilot-instructions.md | D16: 47 | E16: * Use `[]` for empty arrays and *not* `Array.Empty<T>()` | G16: Coding Pattern
A17: dotnet | B17: maui | C17: https://github.com/dotnet/maui/blob/main/.github/copilot-instructions.md | D17: 106 | E17: Direct commits to `main` are strictly prohibited. | F17: prohibited | G17: Commit&PR rule
A18: kubefleet-dev | B18: kubefleet | C18: https://github.com/kubefleet-dev/kubefleet/blob/main/.github/copilot-instructions.md | D18: 32 | E18: - Do **not** use assert libraries; use `cmp.Diff` / `cmp.Equal` from `google/go-cmp` for comparisons | F18: Do **not** | G18: Coding Pattern
A19: wled | B19: WLED | C19: https://github.com/wled/WLED/blob/main/.github/copilot-instructions.md | D19: 7 | E19: Do **not** use that content as actionable review | F19: Do **not** | G19: Code Review
A20: abh | B20: ntppool | C20: https://github.com/abh/ntppool/blob/main/CLAUDE.md | D20: 121 | E20: ❌ **Shadow DOM by default**: Use `inherit-styles="true"` for Web Components | F20: ❌ | G20: Coding Pattern
A21: home-assistant | B21: frontend | C21: https://github.com/home-assistant/frontend/blob/master/CLAUDE.md | D21: 225 | E21: - ❌ "Create New Automation" | F21: ❌ | G21: Writing Style Preference
A22: home-assistant | B22: frontend | C22: https://github.com/home-assistant/frontend/blob/master/CLAUDE.md | D22: 227 | E22: - ❌ "Device Settings" | F22: ❌ | G22: Writing Style Preference
A23: paradigmxyz | B23: reth | C23: https://github.com/paradigmxyz/reth/blob/main/CLAUDE.md | D23: 138 | E23: ❌ **Bad**: Adding new traits and auxiliary types **above** the file's primary type (see [#22133](https://github.com/paradigmxyz/reth/pull/22133)): | F23: ❌ | G23: Coding Style
A24: julep-ai | B24: julep | C24: https://github.com/julep-ai/julep/blob/main/AGENTS.md | D24: 21 | E24: | ❌ Touch `tests/`, `SPEC.md`, or any `*_spec.py` / `*.ward` files (humans own tests & specs). | F24: ❌ | G24: Testing
A25: julep-ai | B25: julep | C25: https://github.com/julep-ai/julep/blob/main/AGENTS.md | D25: 24 | E25: | ❌ Delete or mangle existing `AIDEV-` comments. | F25: ❌ | G25: Documentation
A26: julep-ai | B26: julep | C26: https://github.com/julep-ai/julep/blob/main/AGENTS.md | D26: 28 | E26: | ❌ Re-format code to any other style. | F26: ❌ | G26: Coding Style
A27: julep-ai | B27: julep | C27: https://github.com/julep-ai/julep/blob/main/AGENTS.md | D27: 35 | E27: | ❌ Continue work from a prior prompt after "new task" – start a fresh session. | F27: ❌ | G27: Task Execution
A28: public-ui | B28: kolibri | C28: https://github.com/public-ui/kolibri/blob/master/AGENTS.md | D28: 81 | E28: ❌ **Outdated pattern (removed):** | F28: ❌ | G28: Coding Pattern
... A2505: CapSoftware | B2505: Cap | C2505: https://github.com/CapSoftware/Cap/blob/main/AGENTS.md | D2505: 85 | E2505: - On the client, use `useEffectQuery`/`useEffectMutation` from `@/lib/EffectRuntime`; they already bind the managed runtime and tracing so you shouldn't call `EffectRuntime.run*` directly in components. | F2505: shouldn't | G2505: Coding Pattern
A2506: colinhacks | B2506: zod | C2506: https://github.com/colinhacks/zod/blob/main/CLAUDE.md | D2506: 69 | E2506: - Skip effusive praise: "Great work", "Awesome", "Thanks so much for this", "Thanks for the careful writeup", "you clearly read the RFC". | G2506: Writing Style Preference
A2507: colinhacks | B2507: zod | C2507: https://github.com/colinhacks/zod/blob/main/CLAUDE.md | D2507: 99 | E2507: - Skip emojis in substantive technical writeups. | G2507: Commit&PR rule
A2508: module-federation | B2508: core | C2508: https://github.com/module-federation/core/blob/main/CLAUDE.md | D2508: 111 | E2508: - ✗ Skip running tests after changes | F2508: ✗ | G2508: Testing
A2509: microsoft | B2509: typespec | C2509: https://github.com/microsoft/typespec/blob/main/.github/copilot-instructions.md | D2509: 75 | E2509: - For new features, include a short code block in the changelog entry that showcases the new functionality; skip code blocks for simple bug fixes. | G2509: Commit&PR rule
A2510: microsoft | B2510: vs-threading | C2510: https://github.com/microsoft/vs-threading/blob/main/.github/copilot-instructions.md | D2510: 15 | E2510: When running tests, you should skip the unstable ones by using `-- --filter-not-trait "FailsInCloudTest=true"`. | F2510: should **not** | G2510: Testing
A2511: sybrew | B2511: the-seo-framework | C2511: https://github.com/sybrew/the-seo-framework/blob/master/.github/copilot-instructions.md | D2511: 47 | E2511: Skip ritual closings. | G2511: Writing Style Preference
A2512: coder | B2512: coder | C2512: https://github.com/coder/coder/blob/main/CLAUDE.md | D2512: 3 | E2512: Rule #1: If you want exception to ANY rule, YOU MUST STOP and get explicit permission first. | F2512: STOP | G2512: Task Execution
A2513: Pipelex | B2513: pipelex | C2513: https://github.com/Pipelex/pipelex/blob/main/CLAUDE.md | D2513: 127 | E2513: If you find yourself writing `except Exception`, STOP and ask the user before proceeding. | F2513: STOP | G2513: Task Execution
A2514: RchGrav | B2514: claudebox | C2514: https://github.com/RchGrav/claudebox/blob/main/CLAUDE.md | D2514: 103 | E2514: * `-euo pipefail` stops on non-zero status, undefined vars, or broken pipelines. | F2514: STOP | G2514: Build & Operation
A2515: Skyvern-AI | B2515: skyvern | C2515: https://github.com/Skyvern-AI/skyvern/blob/master/CLAUDE.md | D2515: 7 | E2515: - **Stop services**: `skyvern stop all` | F2515: STOP | G2515: Build & Operation
A2516: steipete | B2516: Peekaboo | C2516: https://github.com/steipete/Peekaboo/blob/main/CLAUDE.md | D2516: 16 | E2516: - Rapid rebuilds while editing Swift: `pnpm run poltergeist:haunt` → check with `pnpm run poltergeist:status`, stop via `pnpm run poltergeist:rest`. | F2516: STOP | G2516: Build & Operation
...

Sheet Results
A1: Label | B1: Category Name | C1: Description | D1: Rule | E1: Example | F1: # | G1: %
A2: Commit&PR rule | B2: Version Control Interaction | C2: Prohibitions on commit behavior, pull request content, branch interaction, and changelog formatting. These instructions govern how the agent interacts with the version control system and collaborative development artifacts. | D2: The instruction refers to commit messages, PR messages, interaction with the repository, commit behavior, etc | E2: Direct commits to `main` are strictly prohibited. | F2: =COUNTIF(Main!G:G,A2) -> 198 | G2: =(F2/J14) -> 0.077891424 | H2: RULES
A3: Task Execution | B3: Workflow and Artifacts Management | C3: Prohibitions on how the agent should manage and execute tasks: workflow sequencing, context loading, task decomposition, parallelism, and general operational behavior during execution. These instructions govern agent autonomy at the process level. | D3: The instruction refers to how the agent should execute tasks, workflow, how it should handle instructions, how to be efficient when executing tasks, and generally how it should act | E3: - **MINIMIZE CONTEXT**: Avoid loading unnecessary files to preserve token efficiency | F3: =COUNTIF(Main!G:G,A3) -> 428 | G3: =(F3/J14) -> 0.16837136 | H3: - During coding, when you are unsure of a category, please come back to this codebook to verify detection rule - You can improve detection rules as you go over new data to be more informative of what they can be assigned to - You can add other categories, if they emerge from the data and they are shared among multiple instructions - If you add a new category, that must be discussed when the step completes, so remember it - If all agree with the new category, add it in this codebook specifying detection rule and an example so that it can be used for next step by all coders
A4: Documentation | B4: Documentation | C4: Prohibitions on the creation, modification, or formatting of documentation artifacts, including Markdown files, inline code comments, and project guidelines. These instructions often constrain unsolicited documentation generation or unauthorized edits to existing artifacts. | D4: The instruction relates to any kind of documentation artifact (.md, code comments, guidelines) and how the agent should interact with them | E4: - ✗ Create documentation unless specifically requested | F4: =COUNTIF(Main!G:G,A4) -> 159 | G4: =(F4/J14) -> 0.062549174
A5: Coding Pattern | B5: Coding Pattern | C5: Prohibitions on how the agent should functionally implement code, including imports, type annotations, design patterns, control flow constructs, and use of specific APIs or libraries. These instructions constrain implementation choices at the logic level. | D5: The instruction refers to how the agent should functionally write code (typings, imports, design patterns, loops, conditions) | E5: - Avoid inline for loops, unless it's ultra-simple and holds on oneline. | F5: =COUNTIF(Main!G:G,A5) -> 755 | G5: =(F5/J14) -> 0.29701023
A6: Code Review | B6: Code Review and Inspection | C6: Prohibitions on how the agent should conduct or participate in code review, including scope of feedback, use of review content as directives, and interaction with artifacts under review. | D6: The instruction mentions how the agent should handle code review, artifact review, and interact with the code written by others | E6: Do **not** use that content as actionable review | F6: =COUNTIF(Main!G:G,A6) -> 21 | G6: =(F6/J14) -> 0.0082612116
A7: Writing Style Preference | B7: Writing and Communication Style | C7: Prohibitions on the agent's use of natural language, covering tone, terminology, abbreviations, formatting conventions, and clarity. These instructions apply to any text the agent produces outside of source code. | D7: The instruction mentions how the agent should write natural language, patterns, clarity, and quality | E7: - **Avoid CAPS for emphasis**: Use bold or italics instead | F7: =COUNTIF(Main!G:G,A7) -> 88 | G7: =(F7/J14) -> 0.034618411
A8: Coding Style | B8: Coding Style | C8: Prohibitions on the stylistic presentation of code, including naming conventions, formatting, file organization, and comment structure. These instructions address how code should look rather than what it should do. | D8: The instruction mentions how the agent should adapt the code style in terms of preferences of how the code should look (not functionality), like names etc. | E8: - Avoid redundant function header comments that merely repeat the function name. | F8: =COUNTIF(Main!G:G,A8) -> 171 | G8: =(F8/J14) -> 0.067269866
A9: Testing | B9: Test Development and Execution | C9: Prohibitions related to test code, test files, testing strategies, and verification artifacts. These instructions restrict what the agent may modify or create in the testing layer, including ownership boundaries between human- and agent-managed test artifacts. | D9: The instruction relates to tests, testing, verification, test files, test code | E9: - **Test simplicity**: Keep tests simple, avoid mocks. | F9: =COUNTIF(Main!G:G,A9) -> 255 | G9: =(F9/J14) -> 0.10031471
A10: Maintainability | B10: Maintainability and Quality | C10: Prohibitions targeting code quality attributes beyond immediate functionality, such as unnecessary complexity, code duplication, over-engineering, and architectural fragility. These instructions reflect long-term maintainability concerns. | D10: The instruction mentions quality attributes of the code that improve maintainability like complexity, readability, etc | E10: **Avoid architectural complexity** - simple functions over design patterns | F10: =COUNTIF(Main!G:G,A10) -> 44 | G10: =(F10/J14) -> 0.017309205
A11: Build & Operation | B11: Build, Operation and Environment | C11: Prohibitions on build processes, compilation, environment setup, and operational tooling such as servers, containers, and CI/CD pipelines. These instructions constrain agent actions that interact with the execution environment rather than the source code itself. | D11: The instruction refers about operational before or after the developement e.g Building, Compiling, etc. Development Environment is also considered as a part of Build & Operation | E11: - Avoid running Docker or external services yourself unless requested; root workflows handle them as needed. | F11: =COUNTIF(Main!G:G,A11) -> 249 | G11: =(F11/J14) -> 0.097954367
A12: Performance | B12: Performance and Efficiency | C12: Prohibitions on implementation choices that could degrade runtime performance or resource efficiency, including unnecessary allocations, inefficient data structures, excessive dependencies, and anti-patterns in hot paths. | D12: The instruction refers to how to create code that is performant, fast, efficient, etc | E12: - Avoid introducing new external dependencies unless it will have a material impact on code readability or performance | F12: =COUNTIF(Main!G:G,A12) -> 49 | G12: =(F12/J14) -> 0.019276161
A13: Security | B13: Security and Privacy | C13: Prohibitions related to security risks, credential handling, secret management, sensitive data exposure, and cybersecurity best practices. These instructions encode hard boundaries against actions that could compromise system or data integrity. | D13: The instruction mentions security threats, secrets, personal informations, or cybersec | E13: - Secrets managed via Azure (Function App / Static Web App settings) – Avoid committing secrets | F13: =COUNTIF(Main!G:G,A13) -> 80 | G13: =(F13/J14) -> 0.031471282
A14: Other | F14: =COUNTIF(Main!G:G,A14) -> 0 | G14: =(F14/J14) -> 0 | I14: TOTAL: | J14: =COUNTA(Main!E2:E2846) -> 2542
A15: NOT_ENOUGH_CONTEXT | D15: It does not have enough contexts | E15: Avoid: | F15: =COUNTIF(Main!G:G,A15) -> 45 | G15: =(F15/J14) -> 0.017702596
F17: =SUM(F1:F15) -> 2542 | G17: =SUM(G2:G15) -> 1

Sheet Step 1
A1: ACF | B1: Instruction | C1: Category | D1: Reason
A2: https://github.com/langchain-ai/langchain/blob/master/CLAUDE.md | B2: - Do **not** cite line numbers; they go stale as soon as the file changes. | C2: Commit&PR rule | D2: cite number is not nessesary
A3: https://github.com/module-federation/core/blob/main/CLAUDE.md | B3: - ✗ Use a single task when multiple would be faster | C3: Task Execution | D3: working with a single task is slower
A4: https://github.com/module-federation/core/blob/main/CLAUDE.md | B4: - ✗ Ask for clarification before launching tasks | C4: Task Execution | D4: Ask for clarification
A5: https://github.com/module-federation/core/blob/main/CLAUDE.md | B5: - ✗ Make tasks dependent on each other | C5: Task Execution | D5: dependency-lock to each other tasks
A6: https://github.com/module-federation/core/blob/main/CLAUDE.md | B6: - ✗ Load entire codebase into a single task | C6: Task Execution | D6: dont load all codebase in a single task
A7: https://github.com/module-federation/core/blob/main/CLAUDE.md | B7: - ✗ Create documentation unless specifically requested | C7: Documentation | D7: dont create documents unrequested, don't do something i did not request
A8: https://github.com/module-federation/core/blob/main/CLAUDE.md | B8: - ✗ Create new files when existing ones can be modified | C8: Task Execution | D8: dont create new things thate we already have
A9: https://github.com/owid/owid-grapher/blob/master/CLAUDE.md | B9: The `makeObservable` call must mention all obserable props, but none of the @computed or @action ones. | C9: Coding Pattern | D9: don't use a particular type of props in the code
A10: https://github.com/saleor/saleor/blob/main/CLAUDE.md | B10: - When asserting to Enum, import enum in a test file and use `assert error.code == MyEnum.SOME_ERROR.name` instead of plain string comparison | C10: Coding Pattern | D10: do not use plain string comparison
A11: https://github.com/zed-industries/zed/blob/main/CLAUDE.md | B11: Do **not** edit `.rules` inline during normal feature/fix work. | C11: Documentation
A12: https://github.com/gluesql/glues/blob/main/AGENTS.md | B12: - Use file-based module declarations; do **not** introduce `mod.rs` files. | C12: Coding Pattern | D12: prohibit the pattern of introduing mod.rs
A13: https://github.com/useautumn/autumn/blob/main/AGENTS.md | B13: - Do **not** remove or bypass logic in `server/src/honoMiddlewares/refreshCacheMiddleware.ts` unless the user explicitly asks to change middleware behavior globally. | C13: Coding Pattern
A14: https://github.com/Azure/fleet/blob/main/.github/copilot-instructions.md | B14: - Do **not** use assert libraries; use `cmp.Diff` / `cmp.Equal` from `google/go-cmp` for comparisons | C14: Coding Pattern
A15: https://github.com/dotnet/java-interop/blob/main/.github/copilot-instructions.md | B15: * Use `""` for empty string and *not* `string.Empty` | C15: Coding Pattern | D15: clearly state about the pattern of the code for empty string
A16: https://github.com/dotnet/java-interop/blob/main/.github/copilot-instructions.md | B16: * Use `[]` for empty arrays and *not* `Array.Empty<T>()` | C16: Coding Pattern | D16: clearly state about the pattern of the code for empty array
A17: https://github.com/dotnet/maui/blob/main/.github/copilot-instructions.md | B17: Direct commits to `main` are strictly prohibited. | C17: Commit&PR rule | D17: its prohibit commiting to main branch
A18: https://github.com/kubefleet-dev/kubefleet/blob/main/.github/copilot-instructions.md | B18: - Do **not** use assert libraries; use `cmp.Diff` / `cmp.Equal` from `google/go-cmp` for comparisons | C18: Coding Pattern | D18: Clarify what can and cannot be done.
A19: https://github.com/wled/WLED/blob/main/.github/copilot-instructions.md | B19: Do **not** use that content as actionable review | C19: Code Review
A20: https://github.com/abh/ntppool/blob/main/CLAUDE.md | B20: ❌ **Shadow DOM by default**: Use `inherit-styles="true"` for Web Components | C20: Coding Pattern
A21: https://github.com/home-assistant/frontend/blob/master/CLAUDE.md | B21: - ❌ "Create New Automation" | C21: Writing Style Preference
A22: https://github.com/home-assistant/frontend/blob/master/CLAUDE.md | B22: - ❌ "Device Settings" | C22: Writing Style Preference
A23: https://github.com/paradigmxyz/reth/blob/main/CLAUDE.md | B23: ❌ **Bad**: Adding new traits and auxiliary types **above** the file's primary type (see [#22133](https://github.com/paradigmxyz/reth/pull/22133)): | C23: Coding Style
A24: https://github.com/julep-ai/julep/blob/main/AGENTS.md | B24: | ❌ Touch `tests/`, `SPEC.md`, or any `*_spec.py` / `*.ward` files (humans own tests & specs). | C24: Testing
A25: https://github.com/julep-ai/julep/blob/main/AGENTS.md | B25: | ❌ Delete or mangle existing `AIDEV-` comments. | C25: Documentation | D25: keep the comment in the code
A26: https://github.com/julep-ai/julep/blob/main/AGENTS.md | B26: | ❌ Re-format code to any other style. | C26: Coding Style | D26: keep code-format consistent
A27: https://github.com/julep-ai/julep/blob/main/AGENTS.md | B27: | ❌ Continue work from a prior prompt after "new task" – start a fresh session. | C27: Task Execution
A28: https://github.com/public-ui/kolibri/blob/master/AGENTS.md | B28: ❌ **Outdated pattern (removed):** | C28: Coding Pattern | D28: outdate pattern
A29: https://github.com/dotnet/docs-desktop/blob/main/.github/copilot-instructions.md | B29: - ❌ Bad: `Getting-Started-With-The-Entity-Framework.md` | C29: Documentation | D29: in the context, they said how to name the file
A30: https://github.com/dotnet/docs-desktop/blob/main/.github/copilot-instructions.md | B30: - ❌ Bad: `configure_logging.md` | C30: Documentation | D30: in the context, they said how to name the file
A31: https://github.com/dotnet/docs-desktop/blob/main/.github/copilot-instructions.md | B31: - ❌ Bad: `DependencyInjectionGuidelines.md` | C31: Documentation | D31: in the context, they said how to name the file
A32: https://github.com/raycast/extensions/blob/main/.github/copilot-instructions.md | B32: - ❌ Incorrect: `## [Bug Fix] - 2024-07-12` | C32: Commit&PR rule
A33: https://github.com/geneontology/go-ontology/blob/master/CLAUDE.md | B33: Similarly, it's generally an anti-pattern to have more than one asserted `is_a`. | C33: Coding Pattern | D33: code anti-pattern mentioned
A34: https://github.com/geneontology/go-ontology/blob/master/CLAUDE.md | B34: A common anti-pattern is using logical definitions where relationships suffice. | C34: Coding Pattern | D34: code anti-pattern mentioned
A35: https://github.com/dotnet/maui/blob/main/.github/copilot-instructions.md | B35: **Anti-pattern:** Writing ad-hoc scripts to parse AzDO build timelines. | C35: Coding Pattern | D35: code anti-pattern mentioned
A36: https://github.com/geneontology/go-ontology/blob/master/.github/copilot-instructions.md | B36: Similarly, it's generally an anti-pattern to have more than one asserted `is_a`. | C36: Coding Pattern | D36: code anti-pattern mentioned
A37: https://github.com/geneontology/go-ontology/blob/master/.github/copilot-instructions.md | B37: A common anti-pattern is using logical definitions where relationships suffice. | C37: Coding Pattern | D37: code anti-pattern mentioned
A38: https://github.com/abh/ntppool/blob/main/CLAUDE.md | B38: - Keep functions focused and avoid over-engineering with design patterns | C38: Maintainability | D38: over-enginnering mentioned.
A39: https://github.com/abh/ntppool/blob/main/CLAUDE.md | B39: **Avoid architectural complexity** - simple functions over design patterns | C39: Maintainability | D39: clearly state about using simpler function more than follow design pattern
A40: https://github.com/abh/ntppool/blob/main/CLAUDE.md | B40: - **`account_id`**: AVOID - use `a` parameter with account token instead | C40: Coding Style | D40: naming rule
...

Sheet Ann1 - Step 2
A1: Column 3 | B1: Instruction | C1: Category
A2: https://github.com/saleor/saleor/blob/main/CLAUDE.md | B2: - Avoid assertion to plain values, if you already have references to existing value. | C2: Testing | F2: Testing
A3: https://github.com/saleor/saleor/blob/main/CLAUDE.md | B3: 1000 rows) to avoid long-running transactions | C3: Task Execution | F3: Task Execution
A4: https://github.com/spylang/spy/blob/main/CLAUDE.md | B4: Avoid writing useless comments: if you need to write a comment, explain WHY the code | C4: Documentation | F4: Documentation
A5: https://github.com/steipete/Peekaboo/blob/main/CLAUDE.md | B5: - SwiftLint config lives in `.swiftlint.yml`; keep new code typed (avoid `Any`), prefer small scoped extensions over large files. | C5: Coding Style | F5: Coding Style
A6: https://github.com/steipete/Peekaboo/blob/main/CLAUDE.md | B6: - Use `./scripts/committer "type(scope): summary" <paths…>` to stage and create commits; avoid raw `git add`. | C6: Commit&PR rule | F6: Commit&PR rule
A7: https://github.com/steipete/Peekaboo/blob/main/CLAUDE.md | B7: - Respect permissions flows documented in `docs/permissions.md`; avoid editing derived artifacts—regenerate via the provided scripts instead. | C7: Build & Operation | F7: Build & Operation
A8: https://github.com/stepfunc/dnp3/blob/main/CLAUDE.md | B8: - **API Design**: Avoid unreachable public items (`unreachable_pub = "deny"`) | C8: Coding Style | F8: Maintainability
A9: https://github.com/thirdweb-dev/js/blob/main/CLAUDE.md | B9: Avoid personal names | C9: Commit&PR rule | F9: Coding Pattern
A10: https://github.com/thirdweb-dev/js/blob/main/CLAUDE.md | B10: - Avoid editor-specific configs; rely on shared settings | C10: Coding Style | F10: Writing Style Preference
A11: https://github.com/thirdweb-dev/js/blob/main/CLAUDE.md | B11: - **Type safety**: Avoid `any` and `unknown` unless unavoidable; narrow generics when possible | C11: Coding Style | F11: Security
A12: https://github.com/thirdweb-dev/js/blob/main/CLAUDE.md | B12: - **Test approach**: Use real function invocations with stub data; avoid brittle mocks | C12: Testing | F12: Performance
A13: https://github.com/thirdweb-dev/js/blob/main/CLAUDE.md | B13: - Return typed results (`Project[]`, `User[]`) – avoid `any` | C13: Coding Style | F13: Code Review
A14: https://github.com/tphakala/birdnet-go/blob/main/CLAUDE.md | B14: Check open PRs to avoid conflicts | C14: Commit&PR rule
A15: https://github.com/truenas/webui/blob/master/CLAUDE.md | B15: - Avoid the `any` type; use `unknown` when type is uncertain | C15: Coding Style
A16: https://github.com/truenas/webui/blob/master/CLAUDE.md | B16: **Avoid** (constructor injection): | C16: Coding Style
A17: https://github.com/wolfi-dev/os/blob/main/CLAUDE.md | B17: - Avoid using obsolete package versions | C17: Maintainability
A18: https://github.com/wolfi-dev/os/blob/main/CLAUDE.md | B18: - When adding tests, always review existing tests and avoid creating redundant tests. | C18: Testing
A19: https://github.com/wvlet/airframe/blob/main/CLAUDE.md | B19: - Avoid `Try[A]` return types - use plain exceptions or domain-specific errors | C19: Coding Style
A20: https://github.com/wvlet/airframe/blob/main/CLAUDE.md | B20: - Avoid mocks to reduce maintenance cost | C20: Maintainability
A21: https://github.com/wvlet/wvlet/blob/main/CLAUDE.md | B21: - Avoid using mock as it increases maintenance cost and creates brittle tests that break when internal implementation changes | C21: Maintainability
A22: https://github.com/wvlet/wvlet/blob/main/CLAUDE.md | B22: - Avoid: `"testParseJSON"`, `"test1"`, `"shouldWork"` | C22: Testing
A23: https://github.com/wvlet/wvlet/blob/main/CLAUDE.md | B23: - Avoid returning Try[A] as it forces monadic-style usage | C23: Coding Style
A24: https://github.com/wvlet/wvlet/blob/main/CLAUDE.md | B24: - **In Scala.js code, avoid using Java-specific libraries** | C24: Coding Pattern
A25: https://github.com/wvlet/wvlet/blob/main/CLAUDE.md | B25: - Avoid: `feature: Add XXX class` | C25: Coding Pattern
... A501: https://github.com/marin-community/marin/blob/main/AGENTS.md | B501: - do not use storage transfer service to move files from one region to another unless the user says "I personally will write grants for Percy to pay for this" | C501: Task Execution

Sheet Ann2 - Step 2
A1: Column 3 | B1: Instruction | C1: Category
A2: https://github.com/saleor/saleor/blob/main/CLAUDE.md | B2: - Avoid assertion to plain values, if you already have references to existing value. | C2: Testing | F2: Testing
A3: https://github.com/saleor/saleor/blob/main/CLAUDE.md | B3: 1000 rows) to avoid long-running transactions | C3: Coding Pattern | F3: Coding Pattern
A4: https://github.com/spylang/spy/blob/main/CLAUDE.md | B4: Avoid writing useless comments: if you need to write a comment, explain WHY the code | C4: Documentation | F4: Documentation
A5: https://github.com/steipete/Peekaboo/blob/main/CLAUDE.md | B5: - SwiftLint config lives in `.swiftlint.yml`; keep new code typed (avoid `Any`), prefer small scoped extensions over large files. | C5: Coding Pattern | F5: Commit&PR rule
A6: https://github.com/steipete/Peekaboo/blob/main/CLAUDE.md | B6: - Use `./scripts/committer "type(scope): summary" <paths…>` to stage and create commits; avoid raw `git add`. | C6: Commit&PR rule | F6: Coding Style
A7: https://github.com/steipete/Peekaboo/blob/main/CLAUDE.md | B7: - Respect permissions flows documented in `docs/permissions.md`; avoid editing derived artifacts—regenerate via the provided scripts instead. | C7: Documentation | F7: Task Execution
A8: https://github.com/stepfunc/dnp3/blob/main/CLAUDE.md | B8: - **API Design**: Avoid unreachable public items (`unreachable_pub = "deny"`) | C8: Coding Pattern | F8: Writing Style Preference
A9: https://github.com/thirdweb-dev/js/blob/main/CLAUDE.md | B9: Avoid personal names | C9: Commit&PR rule | F9: Security
A10: https://github.com/thirdweb-dev/js/blob/main/CLAUDE.md | B10: - Avoid editor-specific configs; rely on shared settings | C10: Coding Style | F10: Build & Operation
A11: https://github.com/thirdweb-dev/js/blob/main/CLAUDE.md | B11: - **Type safety**: Avoid `any` and `unknown` unless unavoidable; narrow generics when possible | C11: Coding Pattern | F11: Maintainability
A12: https://github.com/thirdweb-dev/js/blob/main/CLAUDE.md | B12: - **Test approach**: Use real function invocations with stub data; avoid brittle mocks | C12: Testing | F12: Performance
A13: https://github.com/thirdweb-dev/js/blob/main/CLAUDE.md | B13: - Return typed results (`Project[]`, `User[]`) – avoid `any` | C13: Coding Pattern | F13: Code Review
A14: https://github.com/tphakala/birdnet-go/blob/main/CLAUDE.md | B14: Check open PRs to avoid conflicts | C14: Commit&PR rule | F14: Other
A15: https://github.com/truenas/webui/blob/master/CLAUDE.md | B15: - Avoid the `any` type; use `unknown` when type is uncertain | C15: Coding Pattern
A16: https://github.com/truenas/webui/blob/master/CLAUDE.md | B16: **Avoid** (constructor injection): | C16: Coding Pattern
A17: https://github.com/wolfi-dev/os/blob/main/CLAUDE.md | B17: - Avoid using obsolete package versions | C17: Coding Pattern
A18: https://github.com/wolfi-dev/os/blob/main/CLAUDE.md | B18: - When adding tests, always review existing tests and avoid creating redundant tests. | C18: Testing
A19: https://github.com/wvlet/airframe/blob/main/CLAUDE.md | B19: - Avoid `Try[A]` return types - use plain exceptions or domain-specific errors | C19: Coding Pattern
A20: https://github.com/wvlet/airframe/blob/main/CLAUDE.md | B20: - Avoid mocks to reduce maintenance cost | C20: Testing
A21: https://github.com/wvlet/wvlet/blob/main/CLAUDE.md | B21: - Avoid using mock as it increases maintenance cost and creates brittle tests that break when internal implementation changes | C21: Testing
A22: https://github.com/wvlet/wvlet/blob/main/CLAUDE.md | B22: - Avoid: `"testParseJSON"`, `"test1"`, `"shouldWork"` | C22: Coding Style
A23: https://github.com/wvlet/wvlet/blob/main/CLAUDE.md | B23: - Avoid returning Try[A] as it forces monadic-style usage | C23: Coding Pattern
A24: https://github.com/wvlet/wvlet/blob/main/CLAUDE.md | B24: - **In Scala.js code, avoid using Java-specific libraries** | C24: Coding Pattern
A25: https://github.com/wvlet/wvlet/blob/main/CLAUDE.md | B25: - Avoid: `feature: Add XXX class` | C25: Commit&PR rule
A26: https://github.com/yamadashy/repomix/blob/main/CLAUDE.md | B26: - Maintain feature-based directory structure and avoid dependencies between features | C26: Coding Pattern
... A501: https://github.com/marin-community/marin/blob/main/AGENTS.md | B501: - do not use storage transfer service to move files from one region to another unless the user says "I personally will write grants for Percy to pay for this" | C501: Task Execution

Sheet Step2 Merge
A1: URL | B1: Instruction | C1: Ann1 | D1: Ann2
A2: ='Ann1 - Step 2'!A2 -> https://github.com/saleor/saleor/blob/main/CLAUDE.md | B2: ='Ann1 - Step 2'!B2 -> - Avoid assertion to plain values, if you already have references to existing value. | C2: ='Ann1 - Step 2'!C2 -> Testing | D2: ='Ann2 - Step 2'!C2 -> Testing | E2: =IF(C2=D2, FALSE, TRUE) -> FALSE | G2: =IF(E2=TRUE,F2,D2) -> Testing
A3: ='Ann1 - Step 2'!A3 -> https://github.com/saleor/saleor/blob/main/CLAUDE.md | B3: ='Ann1 - Step 2'!B3 -> 1000 rows) to avoid long-running transactions | C3: ='Ann1 - Step 2'!C3 -> Task Execution | D3: ='Ann2 - Step 2'!C3 -> Coding Pattern | E3: =IF(C3=D3, FALSE, TRUE) -> TRUE | F3: Task Execution | G3: =IF(E3=TRUE,F3,D3) -> Task Execution
A4: ='Ann1 - Step 2'!A4 -> https://github.com/spylang/spy/blob/main/CLAUDE.md | B4: ='Ann1 - Step 2'!B4 -> Avoid writing useless comments: if you need to write a comment, explain WHY the code | C4: ='Ann1 - Step 2'!C4 -> Documentation | D4: ='Ann2 - Step 2'!C4 -> Documentation | E4: =IF(C4=D4, FALSE, TRUE) -> FALSE | G4: =IF(E4=TRUE,F4,D4) -> Documentation
A5: ='Ann1 - Step 2'!A5 -> https://github.com/steipete/Peekaboo/blob/main/CLAUDE.md | B5: ='Ann1 - Step 2'!B5 -> - SwiftLint config lives in `.swiftlint.yml`; keep new code typed (avoid `Any`), prefer small scoped extensions over large files. | C5: ='Ann1 - Step 2'!C5 -> Coding Style | D5: ='Ann2 - Step 2'!C5 -> Coding Pattern | E5: =IF(C5=D5, FALSE, TRUE) -> TRUE | F5: Coding Pattern | G5: =IF(E5=TRUE,F5,D5) -> Coding Pattern
A6: ='Ann1 - Step 2'!A6 -> https://github.com/steipete/Peekaboo/blob/main/CLAUDE.md | B6: ='Ann1 - Step 2'!B6 -> - Use `./scripts/committer "type(scope): summary" <paths…>` to stage and create commits; avoid raw `git add`. | C6: ='Ann1 - Step 2'!C6 -> Commit&PR rule | D6: ='Ann2 - Step 2'!C6 -> Commit&PR rule | E6: =IF(C6=D6, FALSE, TRUE) -> FALSE | G6: =IF(E6=TRUE,F6,D6) -> Commit&PR rule
A7: ='Ann1 - Step 2'!A7 -> https://github.com/steipete/Peekaboo/blob/main/CLAUDE.md | B7: ='Ann1 - Step 2'!B7 -> - Respect permissions flows documented in `docs/permissions.md`; avoid editing derived artifacts—regenerate via the provided scripts instead. | C7: ='Ann1 - Step 2'!C7 -> Build & Operation | D7: ='Ann2 - Step 2'!C7 -> Documentation | E7: =IF(C7=D7, FALSE, TRUE) -> TRUE | F7: Build & Operation | G7: =IF(E7=TRUE,F7,D7) -> Build & Operation
A8: ='Ann1 - Step 2'!A8 -> https://github.com/stepfunc/dnp3/blob/main/CLAUDE.md | B8: ='Ann1 - Step 2'!B8 -> - **API Design**: Avoid unreachable public items (`unreachable_pub = "deny"`) | C8: ='Ann1 - Step 2'!C8 -> Coding Style | D8: ='Ann2 - Step 2'!C8 -> Coding Pattern | E8: =IF(C8=D8, FALSE, TRUE) -> TRUE | F8: Coding Pattern | G8: =IF(E8=TRUE,F8,D8) -> Coding Pattern
A9: ='Ann1 - Step 2'!A9 -> https://github.com/thirdweb-dev/js/blob/main/CLAUDE.md | B9: ='Ann1 - Step 2'!B9 -> Avoid personal names | C9: ='Ann1 - Step 2'!C9 -> Commit&PR rule | D9: ='Ann2 - Step 2'!C9 -> Commit&PR rule | E9: =IF(C9=D9, FALSE, TRUE) -> FALSE | G9: =IF(E9=TRUE,F9,D9) -> Commit&PR rule
A10: ='Ann1 - Step 2'!A10 -> https://github.com/thirdweb-dev/js/blob/main/CLAUDE.md | B10: ='Ann1 - Step 2'!B10 -> - Avoid editor-specific configs; rely on shared settings | C10: ='Ann1 - Step 2'!C10 -> Coding Style | D10: ='Ann2 - Step 2'!C10 -> Coding Style | E10: =IF(C10=D10, FALSE, TRUE) -> FALSE | G10: =IF(E10=TRUE,F10,D10) -> Coding Style
A11: ='Ann1 - Step 2'!A11 -> https://github.com/thirdweb-dev/js/blob/main/CLAUDE.md | B11: ='Ann1 - Step 2'!B11 -> - **Type safety**: Avoid `any` and `unknown` unless unavoidable; narrow generics when possible | C11: ='Ann1 - Step 2'!C11 -> Coding Style | D11: ='Ann2 - Step 2'!C11 -> Coding Pattern | E11: =IF(C11=D11, FALSE, TRUE) -> TRUE | F11: Coding Pattern | G11: =IF(E11=TRUE,F11,D11) -> Coding Pattern
A12: ='Ann1 - Step 2'!A12 -> https://github.com/thirdweb-dev/js/blob/main/CLAUDE.md | B12: ='Ann1 - Step 2'!B12 -> - **Test approach**: Use real function invocations with stub data; avoid brittle mocks | C12: ='Ann1 - Step 2'!C12 -> Testing | D12: ='Ann2 - Step 2'!C12 -> Testing | E12: =IF(C12=D12, FALSE, TRUE) -> FALSE | G12: =IF(E12=TRUE,F12,D12) -> Testing
A13: ='Ann1 - Step 2'!A13 -> https://github.com/thirdweb-dev/js/blob/main/CLAUDE.md | B13: ='Ann1 - Step 2'!B13 -> - Return typed results (`Project[]`, `User[]`) – avoid `any` | C13: ='Ann1 - Step 2'!C13 -> Coding Style | D13: ='Ann2 - Step 2'!C13 -> Coding Pattern | E13: =IF(C13=D13, FALSE, TRUE) -> TRUE | F13: Coding Pattern | G13: =IF(E13=TRUE,F13,D13) -> Coding Pattern
A14: ='Ann1 - Step 2'!A14 -> https://github.com/tphakala/birdnet-go/blob/main/CLAUDE.md | B14: ='Ann1 - Step 2'!B14 -> Check open PRs to avoid conflicts | C14: ='Ann1 - Step 2'!C14 -> Commit&PR rule | D14: ='Ann2 - Step 2'!C14 -> Commit&PR rule | E14: =IF(C14=D14, FALSE, TRUE) -> FALSE | G14: =IF(E14=TRUE,F14,D14) -> Commit&PR rule
A15: ='Ann1 - Step 2'!A15 -> https://github.com/truenas/webui/blob/master/CLAUDE.md | B15: ='Ann1 - Step 2'!B15 -> - Avoid the `any` type; use `unknown` when type is uncertain | C15: ='Ann1 - Step 2'!C15 -> Coding Style | D15: ='Ann2 - Step 2'!C15 -> Coding Pattern | E15: =IF(C15=D15, FALSE, TRUE) -> TRUE | F15: Coding Pattern | G15: =IF(E15=TRUE,F15,D15) -> Coding Pattern
A16: ='Ann1 - Step 2'!A16 -> https://github.com/truenas/webui/blob/master/CLAUDE.md | B16: ='Ann1 - Step 2'!B16 -> **Avoid** (constructor injection): | C16: ='Ann1 - Step 2'!C16 -> Coding Style | D16: ='Ann2 - Step 2'!C16 -> Coding Pattern | E16: =IF(C16=D16, FALSE, TRUE) -> TRUE | F16: Coding Pattern | G16: =IF(E16=TRUE,F16,D16) -> Coding Pattern
A17: ='Ann1 - Step 2'!A17 -> https://github.com/wolfi-dev/os/blob/main/CLAUDE.md | B17: ='Ann1 - Step 2'!B17 -> - Avoid using obsolete package versions | C17: ='Ann1 - Step 2'!C17 -> Maintainability | D17: ='Ann2 - Step 2'!C17 -> Coding Pattern | E17: =IF(C17=D17, FALSE, TRUE) -> TRUE | F17: Build & Operation | G17: =IF(E17=TRUE,F17,D17) -> Build & Operation
A18: ='Ann1 - Step 2'!A18 -> https://github.com/wolfi-dev/os/blob/main/CLAUDE.md | B18: ='Ann1 - Step 2'!B18 -> - When adding tests, always review existing tests and avoid creating redundant tests. | C18: ='Ann1 - Step 2'!C18 -> Testing | D18: ='Ann2 - Step 2'!C18 -> Testing | E18: =IF(C18=D18, FALSE, TRUE) -> FALSE | G18: =IF(E18=TRUE,F18,D18) -> Testing
A19: ='Ann1 - Step 2'!A19 -> https://github.com/wvlet/airframe/blob/main/CLAUDE.md | B19: ='Ann1 - Step 2'!B19 -> - Avoid `Try[A]` return types - use plain exceptions or domain-specific errors | C19: ='Ann1 - Step 2'!C19 -> Coding Style | D19: ='Ann2 - Step 2'!C19 -> Coding Pattern | E19: =IF(C19=D19, FALSE, TRUE) -> TRUE | F19: Coding Pattern | G19: =IF(E19=TRUE,F19,D19) -> Coding Pattern
A20: ='Ann1 - Step 2'!A20 -> https://github.com/wvlet/airframe/blob/main/CLAUDE.md | B20: ='Ann1 - Step 2'!B20 -> - Avoid mocks to reduce maintenance cost | C20: ='Ann1 - Step 2'!C20 -> Maintainability | D20: ='Ann2 - Step 2'!C20 -> Testing | E20: =IF(C20=D20, FALSE, TRUE) -> TRUE | F20: Testing | G20: =IF(E20=TRUE,F20,D20) -> Testing
A21: ='Ann1 - Step 2'!A21 -> https://github.com/wvlet/wvlet/blob/main/CLAUDE.md | B21: ='Ann1 - Step 2'!B21 -> - Avoid using mock as it increases maintenance cost and creates brittle tests that break when internal implementation changes | C21: ='Ann1 - Step 2'!C21 -> Maintainability | D21: ='Ann2 - Step 2'!C21 -> Testing | E21: =IF(C21=D21, FALSE, TRUE) -> TRUE | F21: Testing | G21: =IF(E21=TRUE,F21,D21) -> Testing
A22: ='Ann1 - Step 2'!A22 -> https://github.com/wvlet/wvlet/blob/main/CLAUDE.md | B22: ='Ann1 - Step 2'!B22 -> - Avoid: `"testParseJSON"`, `"test1"`, `"shouldWork"` | C22: ='Ann1 - Step 2'!C22 -> Testing | D22: ='Ann2 - Step 2'!C22 -> Coding Style | E22: =IF(C22=D22, FALSE, TRUE) -> TRUE | F22: Testing | G22: =IF(E22=TRUE,F22,D22) -> Testing
A23: ='Ann1 - Step 2'!A23 -> https://github.com/wvlet/wvlet/blob/main/CLAUDE.md | B23: ='Ann1 - Step 2'!B23 -> - Avoid returning Try[A] as it forces monadic-style usage | C23: ='Ann1 - Step 2'!C23 -> Coding Style | D23: ='Ann2 - Step 2'!C23 -> Coding Pattern | E23: =IF(C23=D23, FALSE, TRUE) -> TRUE | F23: Coding Pattern | G23: =IF(E23=TRUE,F23,D23) -> Coding Pattern
A24: ='Ann1 - Step 2'!A24 -> https://github.com/wvlet/wvlet/blob/main/CLAUDE.md | B24: ='Ann1 - Step 2'!B24 -> - **In Scala.js code, avoid using Java-specific libraries** | C24: ='Ann1 - Step 2'!C24 -> Coding Pattern | D24: ='Ann2 - Step 2'!C24 -> Coding Pattern | E24: =IF(C24=D24, FALSE, TRUE) -> FALSE | G24: =IF(E24=TRUE,F24,D24) -> Coding Pattern
A25: ='Ann1 - Step 2'!A25 -> https://github.com/wvlet/wvlet/blob/main/CLAUDE.md | B25: ='Ann1 - Step 2'!B25 -> - Avoid: `feature: Add XXX class` | C25: ='Ann1 - Step 2'!C25 -> Coding Pattern | D25: ='Ann2 - Step 2'!C25 -> Commit&PR rule | E25: =IF(C25=D25, FALSE, TRUE) -> TRUE | F25: Commit&PR rule | G25: =IF(E25=TRUE,F25,D25) -> Commit&PR rule
A26: ='Ann1 - Step 2'!A26 -> https://github.com/yamadashy/repomix/blob/main/CLAUDE.md | B26: ='Ann1 - Step 2'!B26 -> - Maintain feature-based directory structure and avoid dependencies between features | C26: ='Ann1 - Step 2'!C26 -> Coding Pattern | D26: ='Ann2 - Step 2'!C26 -> Coding Pattern | E26: =IF(C26=D26, FALSE, TRUE) -> FALSE | G26: =IF(E26=TRUE,F26,D26) -> Coding Pattern
A27: ='Ann1 - Step 2'!A27 -> https://github.com/zed-industries/zed/blob/main/CLAUDE.md | B27: ='Ann1 - Step 2'!B27 -> Avoid creating many small files. | C27: ='Ann1 - Step 2'!C27 -> Coding Pattern | D27: ='Ann2 - Step 2'!C27 -> Task Execution | E27: =IF(C27=D27, FALSE, TRUE) -> TRUE | F27: Task Execution | G27: =IF(E27=TRUE,F27,D27) -> Task Execution
A28: ='Ann1 - Step 2'!A28 -> https://github.com/zed-industries/zed/blob/main/CLAUDE.md | B28: ='Ann1 - Step 2'!B28 -> * Avoid using functions that panic like `unwrap()`, instead use mechanisms like `?` to propagate errors. | C28: ='Ann1 - Step 2'!C28 -> Coding Pattern | D28: ='Ann2 - Step 2'!C28 -> Coding Pattern | E28: =IF(C28=D28, FALSE, TRUE) -> FALSE | G28: =IF(E28=TRUE,F28,D28) -> Coding Pattern
A29: ='Ann1 - Step 2'!A29 -> https://github.com/zed-industries/zed/blob/main/CLAUDE.md | B29: ='Ann1 - Step 2'!B29 -> - Example: avoid `let _ = client.request(...).await?;` - use `client.request(...).await?;` instead | C29: ='Ann1 - Step 2'!C29 -> Coding Pattern | D29: ='Ann2 - Step 2'!C29 -> Coding Style | E29: =IF(C29=D29, FALSE, TRUE) -> TRUE | F29: Coding Style | G29: =IF(E29=TRUE,F29,D29) -> Coding Style
A30: ='Ann1 - Step 2'!A30 -> https://github.com/zed-industries/zed/blob/main/CLAUDE.md | B30: ='Ann1 - Step 2'!B30 -> * Avoid creative additions unless explicitly requested | C30: ='Ann1 - Step 2'!C30 -> Coding Pattern | D30: ='Ann2 - Step 2'!C30 -> Task Execution | E30: =IF(C30=D30, FALSE, TRUE) -> TRUE | F30: Task Execution | G30: =IF(E30=TRUE,F30,D30) -> Task Execution
A31: ='Ann1 - Step 2'!A31 -> https://github.com/zed-industries/zed/blob/main/CLAUDE.md | B31: ='Ann1 - Step 2'!B31 -> Trying to update an entity while it's already being updated must be avoided as this will cause a panic. | C31: ='Ann1 - Step 2'!C31 -> Build & Operation | D31: ='Ann2 - Step 2'!C31 -> Task Execution | E31: =IF(C31=D31, FALSE, TRUE) -> TRUE | F31: Coding Pattern | G31: =IF(E31=TRUE,F31,D31) -> Coding Pattern
A32: ='Ann1 - Step 2'!A32 -> https://github.com/zed-industries/zed/blob/main/CLAUDE.md | B32: ='Ann1 - Step 2'!B32 -> `SharedString` is used to avoid copying strings, and is either an `&'static str` or `Arc<str>`. | C32: ='Ann1 - Step 2'!C32 -> Build & Operation | D32: ='Ann2 - Step 2'!C32 -> Coding Pattern | E32: =IF(C32=D32, FALSE, TRUE) -> TRUE | F32: Coding Pattern | G32: =IF(E32=TRUE,F32,D32) -> Coding Pattern
A33: ='Ann1 - Step 2'!A33 -> https://github.com/zed-industries/zed/blob/main/CLAUDE.md | B33: ='Ann1 - Step 2'!B33 -> - Avoid conventional commit prefixes in PR titles (`fix:`, `feat:`, `docs:`, etc.). | C33: ='Ann1 - Step 2'!C33 -> Commit&PR rule | D33: ='Ann2 - Step 2'!C33 -> Commit&PR rule | E33: =IF(C33=D33, FALSE, TRUE) -> FALSE | G33: =IF(E33=TRUE,F33,D33) -> Commit&PR rule
A34: ='Ann1 - Step 2'!A34 -> https://github.com/zed-industries/zed/blob/main/CLAUDE.md | B34: ='Ann1 - Step 2'!B34 -> - Avoid trailing punctuation in PR titles. | C34: ='Ann1 - Step 2'!C34 -> Commit&PR rule | D34: ='Ann2 - Step 2'!C34 -> Commit&PR rule | E34: =IF(C34=D34, FALSE, TRUE) -> FALSE | G34: =IF(E34=TRUE,F34,D34) -> Commit&PR rule
A35: ='Ann1 - Step 2'!A35 -> https://github.com/zed-industries/zed/blob/main/CLAUDE.md | B35: ='Ann1 - Step 2'!B35 -> Avoid architectural descriptions of a crate (module layout, data flow, key types). | C35: ='Ann1 - Step 2'!C35 -> Documentation | D35: ='Ann2 - Step 2'!C35 -> Task Execution | E35: =IF(C35=D35, FALSE, TRUE) -> TRUE | F35: Documentation | G35: =IF(E35=TRUE,F35,D35) -> Documentation
A36: ='Ann1 - Step 2'!A36 -> https://github.com/zenml-io/zenml/blob/main/CLAUDE.md | B36: ='Ann1 - Step 2'!B36 -> - Avoid simple explanatory comments, where it is already clear from the code itself. | C36: ='Ann1 - Step 2'!C36 -> Documentation | D36: ='Ann2 - Step 2'!C36 -> Documentation | E36: =IF(C36=D36, FALSE, TRUE) -> FALSE | G36: =IF(E36=TRUE,F36,D36) -> Documentation
A37: ='Ann1 - Step 2'!A37 -> https://github.com/zenml-io/zenml/blob/main/CLAUDE.md | B37: ='Ann1 - Step 2'!B37 -> - Avoid useless one-line comments interleaved with code that merely narrate the implementation. | C37: ='Ann1 - Step 2'!C37 -> Documentation | D37: ='Ann2 - Step 2'!C37 -> Documentation | E37: =IF(C37=D37, FALSE, TRUE) -> FALSE | G37: =IF(E37=TRUE,F37,D37) -> Documentation
A38: ='Ann1 - Step 2'!A38 -> https://github.com/zenml-io/zenml/blob/main/CLAUDE.md | B38: ='Ann1 - Step 2'!B38 -> > ⚠️ **Integrations should avoid using ZenML private methods** | C38: ='Ann1 - Step 2'!C38 -> Build & Operation | D38: ='Ann2 - Step 2'!C38 -> Coding Pattern | E38: =IF(C38=D38, FALSE, TRUE) -> TRUE | F38: Coding Pattern | G38: =IF(E38=TRUE,F38,D38) -> Coding Pattern
A39: ='Ann1 - Step 2'!A39 -> https://github.com/zenml-io/zenml/blob/main/CLAUDE.md | B39: ='Ann1 - Step 2'!B39 -> - Avoid vague language ("thing", "stuff", "value", "setting") | C39: ='Ann1 - Step 2'!C39 -> Writing Style Preference | D39: ='Ann2 - Step 2'!C39 -> Writing Style Preference | E39: =IF(C39=D39, FALSE, TRUE) -> FALSE | G39: =IF(E39=TRUE,F39,D39) -> Writing Style Preference
A40: ='Ann1 - Step 2'!A40 -> https://github.com/zenml-io/zenml/blob/main/CLAUDE.md | B40: ='Ann1 - Step 2'!B40 -> - Avoid overusing bullet points or other formatting elements | C40: ='Ann1 - Step 2'!C40 -> Writing Style Preference | D40: ='Ann2 - Step 2'!C40 -> Writing Style Preference | E40: =IF(C40=D40, FALSE, TRUE) -> FALSE | G40: =IF(E40=TRUE,F40,D40) -> Writing Style Preference
...

Sheet Step2 Stats
A1: Ann1 | B1: Ann2 | D1: N | E1: =COUNTA(A2:A2462) -> 500
A2: Testing | B2: Testing | D2: Observed agreement | E2: =SUMPRODUCT((A2:A2462<>"")*(A2:A2462=B2:B2462))/E1 -> 0.552 | G2: =IFERROR(__xludf.DUMMYFUNCTION("SORT(UNIQUE(FILTER({A2:A2462;B2:B2462},{A2:A2462;B2:B2462}<>"""")))"),"Build & Operation") -> Build & Operation | H2: {=IF(G2:G2462="",,COUNTIF($A$2:$A2462,G2:G2462)/$E$1)} -> 0.084 | I2: {=IF(G2:G2462="",,COUNTIF($B$2:$B2462,G2:G2462)/$E$1)} -> 0.072 | J2: {=IF(G2:G2462="",,H2:H2462*I2:I2462)} -> 0.006048
A3: Task Execution | B3: Coding Pattern | D3: Expected agreement | E3: =SUM(J2:J2462) -> 0.1504 | G3: =IFERROR(__xludf.DUMMYFUNCTION("""COMPUTED_VALUE"""),"Code Review") -> Code Review | H3: 0.012 | I3: 0.012 | J3: 0.000144
A4: Documentation | B4: Documentation | D4: Cohen’s κ | E4: =IF(1-E3=0,"Kappa undefined",(E2-E3)/(1-E3)) -> 0.47269303 | G4: =IFERROR(__xludf.DUMMYFUNCTION("""COMPUTED_VALUE"""),"Coding Pattern") -> Coding Pattern | H4: 0.284 | I4: 0.334 | J4: 0.094856
A5: Coding Style | B5: Coding Pattern | G5: =IFERROR(__xludf.DUMMYFUNCTION("""COMPUTED_VALUE"""),"Coding Style") -> Coding Style | H5: 0.066 | I5: 0.06 | J5: 0.00396
A6: Commit&PR rule | B6: Commit&PR rule | G6: =IFERROR(__xludf.DUMMYFUNCTION("""COMPUTED_VALUE"""),"Commit&PR rule") -> Commit&PR rule | H6: 0.086 | I6: 0.078 | J6: 0.006708
A7: Build & Operation | B7: Documentation | G7: =IFERROR(__xludf.DUMMYFUNCTION("""COMPUTED_VALUE"""),"Documentation") -> Documentation | H7: 0.096 | I7: 0.096 | J7: 0.009216
A8: Coding Style | B8: Coding Pattern | G8: =IFERROR(__xludf.DUMMYFUNCTION("""COMPUTED_VALUE"""),"Maintainability") -> Maintainability | H8: 0.058 | I8: 0.022 | J8: 0.001276
A9: Commit&PR rule | B9: Commit&PR rule | G9: =IFERROR(__xludf.DUMMYFUNCTION("""COMPUTED_VALUE"""),"Other") -> Other | H9: 0 | I9: 0.004 | J9: 0
A10: Coding Style | B10: Coding Style | G10: =IFERROR(__xludf.DUMMYFUNCTION("""COMPUTED_VALUE"""),"Performance") -> Performance | H10: 0.05 | I10: 0.018 | J10: 0.0009
A11: Coding Style | B11: Coding Pattern | G11: =IFERROR(__xludf.DUMMYFUNCTION("""COMPUTED_VALUE"""),"Security") -> Security | H11: 0.022 | I11: 0.02 | J11: 0.00044
A12: Testing | B12: Testing | G12: =IFERROR(__xludf.DUMMYFUNCTION("""COMPUTED_VALUE"""),"Task Execution") -> Task Execution | H12: 0.104 | I12: 0.16 | J12: 0.01664
A13: Coding Style | B13: Coding Pattern | G13: =IFERROR(__xludf.DUMMYFUNCTION("""COMPUTED_VALUE"""),"Testing") -> Testing | H13: 0.092 | I13: 0.098 | J13: 0.009016
A14: Commit&PR rule | B14: Commit&PR rule | G14: =IFERROR(__xludf.DUMMYFUNCTION("""COMPUTED_VALUE"""),"Writing Style Preference") -> Writing Style Preference | H14: 0.046 | I14: 0.026 | J14: 0.001196
A15: Coding Style | B15: Coding Pattern | H15: 0 | I15: 0 | J15: 0
A16: Coding Style | B16: Coding Pattern | H16: 0 | I16: 0 | J16: 0
A17: Maintainability | B17: Coding Pattern | H17: 0 | I17: 0 | J17: 0
A18: Testing | B18: Testing | H18: 0 | I18: 0 | J18: 0
A19: Coding Style | B19: Coding Pattern | H19: 0 | I19: 0 | J19: 0
A20: Maintainability | B20: Testing | H20: 0 | I20: 0 | J20: 0
A21: Maintainability | B21: Testing | H21: 0 | I21: 0 | J21: 0
A22: Testing | B22: Coding Style | H22: 0 | I22: 0 | J22: 0
A23: Coding Style | B23: Coding Pattern | H23: 0 | I23: 0 | J23: 0
A24: Coding Pattern | B24: Coding Pattern | H24: 0 | I24: 0 | J24: 0
A25: Coding Pattern | B25: Commit&PR rule | H25: 0 | I25: 0 | J25: 0
A26: Coding Pattern | B26: Coding Pattern | H26: 0 | I26: 0 | J26: 0
... A501: Task Execution | B501: Task Execution | H501: 0 | I501: 0 | J501: 0
H502: 0 | I502: 0 | J502: 0
H503: 0 | I503: 0 | J503: 0
H504: 0 | I504: 0 | J504: 0
H505: 0 | I505: 0 | J505: 0
H506: 0 | I506: 0 | J506: 0
H507: 0 | I507: 0 | J507: 0
H508: 0 | I508: 0 | J508: 0
H509: 0 | I509: 0 | J509: 0
H510: 0 | I510: 0 | J510: 0
H511: 0 | I511: 0 | J511: 0
H512: 0 | I512: 0 | J512: 0
H513: 0 | I513: 0 | J513: 0
... H2462: 0 | I2462: 0 | J2462: 0

Sheet Ann1 - Step 3
A1: Column 3 | B1: Instruction | C1: Category | D1: Exist in other sheets
A2: https://github.com/marin-community/marin/blob/main/AGENTS.md | B2: Do not restate the code. | C2: Documentation | D2: 0
A3: https://github.com/marin-community/marin/blob/main/AGENTS.md | B3: Do not create parallel implementations. | C3: Coding Pattern | D3: 0
A4: https://github.com/marin-community/marin/blob/main/AGENTS.md | B4: Do not relax tolerances or hack around failures. | C4: Testing | D4: 0
A5: https://github.com/microsoft/mcp-for-beginners/blob/main/AGENTS.md | B5: - **translations/**: Language-specific versions (auto-generated, do not edit directly) | C5: Documentation | D5: 0
A6: https://github.com/microsoft/mcp-for-beginners/blob/main/AGENTS.md | B6: - **Do NOT manually edit** files in `translations/` directory | C6: Documentation | D6: 0
A7: https://github.com/microsoft/mcp-for-beginners/blob/main/AGENTS.md | B7: - Do not directly edit files in `translations/` directory | C7: Documentation | D7: 0
A8: https://github.com/microsoft/mcp-for-beginners/blob/main/AGENTS.md | B8: - Do not edit `translated_images/` directory | C8: Documentation | D8: 0
A9: https://github.com/msgbyte/tianji/blob/master/AGENTS.md | B9: When generating code, **do not modify** any JSON files in `src/client/public/locales`. | C9: Task Execution | D9: 0
A10: https://github.com/openai/openai-agents-python/blob/main/AGENTS.md | B10: Do not treat branch-local interface churn or unreleased post-tag changes on `main` as breaking by default; prefer direct replacement over compatibility layers in those cases, and renumber or squash unreleased persisted schemas before release when the intermediate snapshots are intentionally unsupported. | C10: Commit&PR rule | D10: 1
A11: https://github.com/openai/openai-agents-python/blob/main/AGENTS.md | B11: Do not insert new constructor parameters or dataclass fields in the middle of existing public order. | C11: Coding Pattern | D11: 1
A12: https://github.com/openai/openai-agents-python/blob/main/AGENTS.md | B12: - Prefer keyword arguments at call sites to reduce accidental breakage, but do not rely on this to justify breaking positional compatibility for public APIs. | C12: Coding Pattern | D12: 1
A13: https://github.com/openai/openai-agents-python/blob/main/AGENTS.md | B13: - `docs/`: MkDocs documentation source; do not edit translated docs under `docs/ja`, `docs/ko`, or `docs/zh` (they are generated). | C13: Documentation | D13: 1
... A1943: https://github.com/dailydotdev/apps/blob/main/CLAUDE.md | B1943: - ❌ **Wrong**: Local `stripHtml()` in webapp-only file | C1943: Coding Pattern | D1943: 0

Sheet Ann2 - Step 3
A1: Column 3 | B1: Instruction | C1: Category | D1: Exist in other sheets
A2: https://github.com/marin-community/marin/blob/main/AGENTS.md | B2: Do not restate the code. | C2: Documentation | D2: 0
A3: https://github.com/marin-community/marin/blob/main/AGENTS.md | B3: Do not create parallel implementations. | C3: Coding Pattern | D3: 0
A4: https://github.com/marin-community/marin/blob/main/AGENTS.md | B4: Do not relax tolerances or hack around failures. | C4: Testing | D4: 0
A5: https://github.com/microsoft/mcp-for-beginners/blob/main/AGENTS.md | B5: - **translations/**: Language-specific versions (auto-generated, do not edit directly) | C5: Documentation | D5: 0
A6: https://github.com/microsoft/mcp-for-beginners/blob/main/AGENTS.md | B6: - **Do NOT manually edit** files in `translations/` directory | C6: Documentation | D6: 0
A7: https://github.com/microsoft/mcp-for-beginners/blob/main/AGENTS.md | B7: - Do not directly edit files in `translations/` directory | C7: Documentation | D7: 0
A8: https://github.com/microsoft/mcp-for-beginners/blob/main/AGENTS.md | B8: - Do not edit `translated_images/` directory | C8: Documentation | D8: 0
A9: https://github.com/msgbyte/tianji/blob/master/AGENTS.md | B9: When generating code, **do not modify** any JSON files in `src/client/public/locales`. | C9: Task Execution | D9: 0
A10: https://github.com/openai/openai-agents-python/blob/main/AGENTS.md | B10: Do not treat branch-local interface churn or unreleased post-tag changes on `main` as breaking by default; prefer direct replacement over compatibility layers in those cases, and renumber or squash unreleased persisted schemas before release when the intermediate snapshots are intentionally unsupported. | C10: Commit&PR rule | D10: 1
A11: https://github.com/openai/openai-agents-python/blob/main/AGENTS.md | B11: Do not insert new constructor parameters or dataclass fields in the middle of existing public order. | C11: Coding Pattern | D11: 1
A12: https://github.com/openai/openai-agents-python/blob/main/AGENTS.md | B12: - Prefer keyword arguments at call sites to reduce accidental breakage, but do not rely on this to justify breaking positional compatibility for public APIs. | C12: Coding Pattern | D12: 1
A13: https://github.com/openai/openai-agents-python/blob/main/AGENTS.md | B13: - `docs/`: MkDocs documentation source; do not edit translated docs under `docs/ja`, `docs/ko`, or `docs/zh` (they are generated). | C13: Documentation | D13: 1
... A1943: https://github.com/dailydotdev/apps/blob/main/CLAUDE.md | B1943: - ❌ **Wrong**: Local `stripHtml()` in webapp-only file | C1943: Coding Pattern | D1943: 0

Sheet Step3 Merge
A1: Column 3 | B1: Instruction | C1: Ann1 | D1: Ann2 | F1: Final
A2: https://github.com/marin-community/marin/blob/main/AGENTS.md | B2: Do not restate the code. | C2: ='Ann1 - Step 3'!C2 -> Documentation | D2: ='Ann2 - Step 3'!C2 -> Documentation | E2: =IF(C2=D2, FALSE, TRUE) -> FALSE | G2: =IF(E2=TRUE,F2,D2) -> Documentation
A3: https://github.com/marin-community/marin/blob/main/AGENTS.md | B3: Do not create parallel implementations. | C3: ='Ann1 - Step 3'!C3 -> Coding Pattern | D3: ='Ann2 - Step 3'!C3 -> Coding Pattern | E3: =IF(C3=D3, FALSE, TRUE) -> FALSE | G3: =IF(E3=TRUE,F3,D3) -> Coding Pattern
A4: https://github.com/marin-community/marin/blob/main/AGENTS.md | B4: Do not relax tolerances or hack around failures. | C4: ='Ann1 - Step 3'!C4 -> Testing | D4: ='Ann2 - Step 3'!C4 -> Testing | E4: =IF(C4=D4, FALSE, TRUE) -> FALSE | G4: =IF(E4=TRUE,F4,D4) -> Testing
A5: https://github.com/microsoft/mcp-for-beginners/blob/main/AGENTS.md | B5: - **translations/**: Language-specific versions (auto-generated, do not edit directly) | C5: ='Ann1 - Step 3'!C5 -> Documentation | D5: ='Ann2 - Step 3'!C5 -> Documentation | E5: =IF(C5=D5, FALSE, TRUE) -> FALSE | G5: =IF(E5=TRUE,F5,D5) -> Documentation
A6: https://github.com/microsoft/mcp-for-beginners/blob/main/AGENTS.md | B6: - **Do NOT manually edit** files in `translations/` directory | C6: ='Ann1 - Step 3'!C6 -> Documentation | D6: ='Ann2 - Step 3'!C6 -> Documentation | E6: =IF(C6=D6, FALSE, TRUE) -> FALSE | G6: =IF(E6=TRUE,F6,D6) -> Documentation
A7: https://github.com/microsoft/mcp-for-beginners/blob/main/AGENTS.md | B7: - Do not directly edit files in `translations/` directory | C7: ='Ann1 - Step 3'!C7 -> Documentation | D7: ='Ann2 - Step 3'!C7 -> Documentation | E7: =IF(C7=D7, FALSE, TRUE) -> FALSE | G7: =IF(E7=TRUE,F7,D7) -> Documentation
A8: https://github.com/microsoft/mcp-for-beginners/blob/main/AGENTS.md | B8: - Do not edit `translated_images/` directory | C8: ='Ann1 - Step 3'!C8 -> Documentation | D8: ='Ann2 - Step 3'!C8 -> Documentation | E8: =IF(C8=D8, FALSE, TRUE) -> FALSE | G8: =IF(E8=TRUE,F8,D8) -> Documentation
